[2021-02-23 14:58:43,628] {taskinstance.py:851} INFO - Dependencies all met for <TaskInstance: example_passing_params_via_test_command.also_run_this 2021-02-22T00:02:00+00:00 [queued]>
[2021-02-23 14:58:43,917] {taskinstance.py:851} INFO - Dependencies all met for <TaskInstance: example_passing_params_via_test_command.also_run_this 2021-02-22T00:02:00+00:00 [queued]>
[2021-02-23 14:58:43,940] {taskinstance.py:1042} INFO - 
--------------------------------------------------------------------------------
[2021-02-23 14:58:43,949] {taskinstance.py:1043} INFO - Starting attempt 1 of 1
[2021-02-23 14:58:43,951] {taskinstance.py:1044} INFO - 
--------------------------------------------------------------------------------
[2021-02-23 14:58:44,059] {taskinstance.py:1063} INFO - Executing <Task(BashOperator): also_run_this> on 2021-02-22T00:02:00+00:00
[2021-02-23 14:58:44,110] {standard_task_runner.py:52} INFO - Started process 236 to run task
[2021-02-23 14:58:44,327] {standard_task_runner.py:76} INFO - Running: ['airflow', 'tasks', 'run', 'example_passing_params_via_test_command', 'also_run_this', '2021-02-22T00:02:00+00:00', '--job-id', '82', '--pool', 'default_pool', '--raw', '--subdir', '/home/airflow/.local/lib/python3.6/site-packages/airflow/example_dags/example_passing_params_via_test_command.py', '--cfg-path', '/tmp/tmpeoo5qg8u', '--error-file', '/tmp/tmpgasnwkgz']
[2021-02-23 14:58:44,339] {standard_task_runner.py:77} INFO - Job 82: Subtask also_run_this
[2021-02-23 14:58:47,907] {logging_mixin.py:104} INFO - Running <TaskInstance: example_passing_params_via_test_command.also_run_this 2021-02-22T00:02:00+00:00 [running]> on host 0513e3a4eab6
[2021-02-23 14:58:49,442] {taskinstance.py:1455} ERROR - 'dict object' has no attribute 'foo'
Traceback (most recent call last):
  File "/home/airflow/.local/lib/python3.6/site-packages/airflow/models/taskinstance.py", line 1112, in _run_raw_task
    self._prepare_and_execute_task_with_callbacks(context, task)
  File "/home/airflow/.local/lib/python3.6/site-packages/airflow/models/taskinstance.py", line 1249, in _prepare_and_execute_task_with_callbacks
    self.render_templates(context=context)
  File "/home/airflow/.local/lib/python3.6/site-packages/airflow/models/taskinstance.py", line 1750, in render_templates
    self.task.render_template_fields(context)
  File "/home/airflow/.local/lib/python3.6/site-packages/airflow/models/baseoperator.py", line 859, in render_template_fields
    self._do_render_template_fields(self, self.template_fields, context, jinja_env, set())
  File "/home/airflow/.local/lib/python3.6/site-packages/airflow/models/baseoperator.py", line 872, in _do_render_template_fields
    rendered_content = self.render_template(content, context, jinja_env, seen_oids)
  File "/home/airflow/.local/lib/python3.6/site-packages/airflow/models/baseoperator.py", line 909, in render_template
    return jinja_env.from_string(content).render(**context)
  File "/home/airflow/.local/lib/python3.6/site-packages/jinja2/environment.py", line 1090, in render
    self.environment.handle_exception()
  File "/home/airflow/.local/lib/python3.6/site-packages/jinja2/environment.py", line 832, in handle_exception
    reraise(*rewrite_traceback_stack(source=source))
  File "/home/airflow/.local/lib/python3.6/site-packages/jinja2/_compat.py", line 28, in reraise
    raise value.with_traceback(tb)
  File "<template>", line 2, in top-level template code
jinja2.exceptions.UndefinedError: 'dict object' has no attribute 'foo'
[2021-02-23 14:58:49,532] {taskinstance.py:1503} INFO - Marking task as FAILED. dag_id=example_passing_params_via_test_command, task_id=also_run_this, execution_date=20210222T000200, start_date=20210223T145843, end_date=20210223T145849
[2021-02-23 14:58:49,906] {local_task_job.py:188} WARNING - State of this instance has been externally set to failed. Terminating instance.
[2021-02-23 14:58:50,041] {process_utils.py:100} INFO - Sending Signals.SIGTERM to GPID 236
[2021-02-23 14:58:50,683] {process_utils.py:66} INFO - Process psutil.Process(pid=236, status='terminated', exitcode=1, started='14:58:43') (236) terminated with exit code 1
